Workbook
Name _Hlk24994008: Datos!$B$43

Sheet Filtrado de Información
A1: Defunciones registradas (mortalidad general) | L1: Nacimientos registrados
A2: Ent y mun de residencia : Hidalgo | L2: Ent y mun reside madre : Hidalgo
A4: Consulta de: Defunciones registradas Por: Edad, Año de registro y Año de ocurrencia Según: Sexo | L4: Consulta de: Nacimientos registrados Por: Año de registro y Sexo Según: Año de ocurrencia
D6: Total | E6: Hombre | F6: Mujer | G6: No especificado | N6: 2009 | O6: 2010 | P6: 2011 | Q6: 2012 | R6: 2013 | S6: 2014 | T6: 2015 | U6: 2016 | V6: 2017 | W6: 2018 | X6: 2019 | Y6: 2020 | Z6: 2021 | AA6: 2022 | AB6: 2023 | AC6: 2024
A7: Total | B7: 1990 | C7: Total | D7: 10,029 | E7: 5,735 | F7: 4,273 | G7: 21 | L7: 2009 | M7: Total | N7: 39,537
A8: Total | B8: 1991 | C8: Total | D8: 9,362 | E8: 5,233 | F8: 4,121 | G8: 8 | L8: 2009 | M8: Hombre | N8: 20,101
A9: Total | B9: 1992 | C9: Total | D9: 9,623 | E9: 5,453 | F9: 4,170 | L9: 2009 | M9: Mujer | N9: 19,427
A10: Total | B10: 1993 | C10: Total | D10: 9,559 | E10: 5,353 | F10: 4,200 | G10: 6 | L10: 2009 | M10: No especificado | N10: 9
A11: Total | B11: 1994 | C11: Total | D11: 9,583 | E11: 5,416 | F11: 4,165 | G11: 2 | L11: 2010 | M11: Total | N11: 12,281 | O11: 39,591
A12: Total | B12: 1995 | C12: Total | D12: 9,907 | E12: 5,631 | F12: 4,272 | G12: 4 | L12: 2010 | M12: Hombre | N12: 6,208 | O12: 20,191
A13: Total | B13: 1996 | C13: Total | D13: 9,943 | E13: 5,565 | F13: 4,378 | L13: 2010 | M13: Mujer | N13: 6,073 | O13: 19,400
A14: Total | B14: 1997 | C14: Total | D14: 9,781 | E14: 5,443 | F14: 4,338 | L14: 2011 | M14: Total | N14: 1,545 | O14: 12,750 | P14: 41,112
A15: Total | B15: 1998 | C15: Total | D15: 10,136 | E15: 5,669 | F15: 4,466 | G15: 1 | L15: 2011 | M15: Hombre | N15: 784 | O15: 6,481 | P15: 21,073
A16: Total | B16: 1999 | C16: Total | D16: 10,038 | E16: 5,568 | F16: 4,469 | G16: 1 | L16: 2011 | M16: Mujer | N16: 761 | O16: 6,269 | P16: 20,033
A17: Total | B17: 2000 | C17: Total | D17: 9,113 | E17: 5,083 | F17: 4,028 | G17: 2 | L17: 2011 | M17: No especificado | P17: 6
A18: Total | B18: 2001 | C18: Total | D18: 9,693 | E18: 5,420 | F18: 4,268 | G18: 5 | L18: 2012 | M18: Total | N18: 898 | O18: 1,448 | P18: 11,902 | Q18: 40,521
A19: Total | B19: 2002 | C19: Total | D19: 10,151 | E19: 5,748 | F19: 4,402 | G19: 1 | L19: 2012 | M19: Hombre | N19: 453 | O19: 729 | P19: 6,076 | Q19: 20,507
A20: Total | B20: 2003 | C20: Total | D20: 10,089 | E20: 5,661 | F20: 4,427 | G20: 1 | L20: 2012 | M20: Mujer | N20: 444 | O20: 719 | P20: 5,825 | Q20: 19,967
A21: Total | B21: 2004 | C21: Total | D21: 10,561 | E21: 5,888 | F21: 4,671 | G21: 2 | L21: 2012 | M21: No especificado | N21: 1 | P21: 1 | Q21: 47
A22: Total | B22: 2005 | C22: Total | D22: 10,955 | E22: 6,043 | F22: 4,904 | G22: 8 | L22: 2013 | M22: Total | N22: 684 | O22: 862 | P22: 1,322 | Q22: 12,014 | R22: 39,582
A23: Total | B23: 2006 | C23: Total | D23: 10,926 | E23: 6,064 | F23: 4,862 | L23: 2013 | M23: Hombre | N23: 326 | O23: 431 | P23: 638 | Q23: 6,076 | R23: 19,997
A24: Total | B24: 2007 | C24: Total | D24: 11,628 | E24: 6,351 | F24: 5,277 | L24: 2013 | M24: Mujer | N24: 358 | O24: 431 | P24: 684 | Q24: 5,938 | R24: 19,571
A25: Total | B25: 2008 | C25: Total | D25: 12,363 | E25: 6,784 | F25: 5,577 | G25: 2 | L25: 2013 | M25: No especificado | R25: 14
A26: Total | B26: 2009 | C26: Total | D26: 12,900 | E26: 7,264 | F26: 5,609 | G26: 27 | L26: 2014 | M26: Total | N26: 302 | O26: 477 | P26: 648 | Q26: 899 | R26: 11,391 | S26: 37,665
A27: Total | B27: 2010 | C27: Total | D27: 12,990 | E27: 7,149 | F27: 5,839 | G27: 2 | L27: 2014 | M27: Hombre | N27: 138 | O27: 231 | P27: 301 | Q27: 465 | R27: 5,836 | S27: 19,306
A28: Total | B28: 2011 | C28: Total | D28: 13,150 | E28: 7,233 | F28: 5,909 | G28: 8 | L28: 2014 | M28: Mujer | N28: 164 | O28: 246 | P28: 347 | Q28: 434 | R28: 5,555 | S28: 18,359
A29: Total | B29: 2012 | C29: Total | D29: 13,246 | E29: 7,168 | F29: 6,065 | G29: 13 | L29: 2015 | M29: Total | N29: 168 | O29: 246 | P29: 448 | Q29: 585 | R29: 959 | S29: 11,122 | T29: 38,034
A30: Total | B30: 2013 | C30: Total | D30: 13,878 | E30: 7,520 | F30: 6,352 | G30: 6 | L30: 2015 | M30: Hombre | N30: 95 | O30: 123 | P30: 226 | Q30: 279 | R30: 468 | S30: 5,638 | T30: 19,409
A31: Total | B31: 2014 | C31: Total | D31: 14,142 | E31: 7,719 | F31: 6,415 | G31: 8 | L31: 2015 | M31: Mujer | N31: 73 | O31: 123 | P31: 222 | Q31: 306 | R31: 491 | S31: 5,484 | T31: 18,625
A32: Total | B32: 2015 | C32: Total | D32: 14,595 | E32: 7,861 | F32: 6,727 | G32: 7 | L32: 2016 | M32: Total | N32: 71 | O32: 150 | P32: 238 | Q32: 404 | R32: 501 | S32: 896 | T32: 10,832 | U32: 37,761
A33: Total | B33: 2016 | C33: Total | D33: 15,391 | E33: 8,475 | F33: 6,910 | G33: 6 | L33: 2016 | M33: Hombre | N33: 38 | O33: 84 | P33: 119 | Q33: 209 | R33: 253 | S33: 459 | T33: 5,595 | U33: 19,114
A34: Total | B34: 2017 | C34: Total | D34: 15,675 | E34: 8,526 | F34: 7,147 | G34: 2 | L34: 2016 | M34: Mujer | N34: 33 | O34: 66 | P34: 119 | Q34: 195 | R34: 248 | S34: 437 | T34: 5,237 | U34: 18,647
A35: Total | B35: 2018 | C35: Total | D35: 15,945 | E35: 8,691 | F35: 7,253 | G35: 1 | L35: 2017 | M35: Total | N35: 31 | O35: 52 | P35: 133 | Q35: 219 | R35: 389 | S35: 464 | T35: 896 | U35: 10,195 | V35: 36,656
A36: Total | B36: 2019 | C36: Total | D36: 16,414 | E36: 9,137 | F36: 7,275 | G36: 2 | L36: 2017 | M36: Hombre | N36: 16 | O36: 30 | P36: 74 | Q36: 108 | R36: 204 | S36: 230 | T36: 459 | U36: 5,148 | V36: 18,520
A37: Total | B37: 2020 | C37: Total | D37: 22,655 | E37: 13,071 | F37: 9,583 | G37: 1 | L37: 2017 | M37: Mujer | N37: 15 | O37: 22 | P37: 59 | Q37: 111 | R37: 185 | S37: 234 | T37: 437 | U37: 5,047 | V37: 18,136
A38: Total | B38: 2021 | C38: Total | D38: 25,106 | E38: 14,557 | F38: 10,548 | G38: 1 | L38: 2018 | M38: Total | N38: 56 | O38: 51 | P38: 63 | Q38: 116 | R38: 212 | S38: 396 | T38: 468 | U38: 852 | V38: 10,092 | W38: 34,542
A39: Total | B39: 2022 | C39: Total | D39: 18,575 | E39: 10,217 | F39: 8,355 | G39: 3 | L39: 2018 | M39: Hombre | N39: 24 | O39: 30 | P39: 31 | Q39: 61 | R39: 110 | S39: 190 | T39: 230 | U39: 447 | V39: 5,049 | W39: 17,674
A40: Total | B40: 2023 | C40: Total | D40: 17,631 | E40: 9,646 | F40: 7,984 | G40: 1 | L40: 2018 | M40: Mujer | N40: 32 | O40: 21 | P40: 32 | Q40: 55 | R40: 102 | S40: 206 | T40: 238 | U40: 405 | V40: 5,043 | W40: 16,868
A41: Total | B41: 2024 | C41: Total | D41: 18,523 | E41: 10,206 | F41: 8,316 | G41: 1 | L41: 2019 | M41: Total | N41: 41 | O41: 43 | P41: 39 | Q41: 54 | R41: 83 | S41: 177 | T41: 338 | U41: 391 | V41: 750 | W41: 9,041 | X41: 32,481
A42: Menores de 1 año | B42: 1990 | C42: Total | D42: 1,534 | E42: 876 | F42: 644 | G42: 14 | L42: 2019 | M42: Hombre | N42: 27 | O42: 19 | P42: 17 | Q42: 26 | R42: 40 | S42: 104 | T42: 191 | U42: 186 | V42: 389 | W42: 4,641 | X42: 16,559
...

Sheet Datos
B2: Cuadro 1
B3: Hidalgo: nacidos vivos y defunciones de menores de 1 año, 2009-2024
B5: Año | C5: Nacimientos | E5: Defunciones de menores de 1 año
C6: Hombres | D6: Mujeres | E6: Hombres | F6: Mujeres
B7: 2009 | C7: ='Filtrado de Información'!N8 -> 20,101 | D7: ='Filtrado de Información'!N9 -> 19,427 | E7: ='Filtrado de Información'!E61 -> 331 | F7: ='Filtrado de Información'!F61 -> 251
B8: 2010 | C8: ='Filtrado de Información'!O12 -> 20,191 | D8: ='Filtrado de Información'!O13 -> 19,400 | E8: ='Filtrado de Información'!E62 -> 351 | F8: ='Filtrado de Información'!F62 -> 251
B9: 2011 | C9: ='Filtrado de Información'!P15 -> 21,073 | D9: ='Filtrado de Información'!P16 -> 20,033 | E9: ='Filtrado de Información'!E63 -> 360 | F9: ='Filtrado de Información'!F63 -> 271
B10: 2012 | C10: ='Filtrado de Información'!Q19 -> 20,507 | D10: ='Filtrado de Información'!Q20 -> 19,967 | E10: ='Filtrado de Información'!E64 -> 361 | F10: ='Filtrado de Información'!F64 -> 287
B11: 2013 | C11: ='Filtrado de Información'!R23 -> 19,997 | D11: ='Filtrado de Información'!R24 -> 19,571 | E11: ='Filtrado de Información'!E65 -> 358 | F11: ='Filtrado de Información'!F65 -> 252
B12: 2014 | C12: ='Filtrado de Información'!S27 -> 19,306 | D12: ='Filtrado de Información'!S28 -> 18,359 | E12: ='Filtrado de Información'!E66 -> 332 | F12: ='Filtrado de Información'!F66 -> 255
B13: 2015 | C13: ='Filtrado de Información'!T30 -> 19,409 | D13: ='Filtrado de Información'!T31 -> 18,625 | E13: ='Filtrado de Información'!E67 -> 318 | F13: ='Filtrado de Información'!F67 -> 268
B14: 2016 | C14: ='Filtrado de Información'!U33 -> 19,114 | D14: ='Filtrado de Información'!U34 -> 18,647 | E14: ='Filtrado de Información'!E68 -> 277 | F14: ='Filtrado de Información'!F68 -> 245
B15: 2017 | C15: ='Filtrado de Información'!V36 -> 18,520 | D15: ='Filtrado de Información'!V37 -> 18,136 | E15: ='Filtrado de Información'!E69 -> 295 | F15: ='Filtrado de Información'!F69 -> 214
B16: 2018 | C16: ='Filtrado de Información'!W39 -> 17,674 | D16: ='Filtrado de Información'!W40 -> 16,868 | E16: ='Filtrado de Información'!E70 -> 263 | F16: ='Filtrado de Información'!F70 -> 215
B17: 2019 | C17: ='Filtrado de Información'!X42 -> 16,559 | D17: ='Filtrado de Información'!X43 -> 15,922 | E17: ='Filtrado de Información'!E71 -> 277 | F17: ='Filtrado de Información'!F71 -> 194
B18: 2020 | C18: ='Filtrado de Información'!Y45 -> 14,000 | D18: ='Filtrado de Información'!Y46 -> 13,629 | E18: ='Filtrado de Información'!E72 -> 189 | F18: ='Filtrado de Información'!F72 -> 152
B19: 2021 | C19: ='Filtrado de Información'!Z48 -> 13,524 | D19: ='Filtrado de Información'!Z49 -> 12,860 | E19: ='Filtrado de Información'!E73 -> 226 | F19: ='Filtrado de Información'!F73 -> 192
B20: 2022 | C20: ='Filtrado de Información'!AA51 -> 13632 | D20: ='Filtrado de Información'!AA52 -> 13264 | E20: ='Filtrado de Información'!E74 -> 248 | F20: ='Filtrado de Información'!F74 -> 196
B21: 2023 | C21: ='Filtrado de Información'!AB54 -> 13,217 | D21: ='Filtrado de Información'!AB55 -> 12,991 | E21: ='Filtrado de Información'!E75 -> 246 | F21: ='Filtrado de Información'!F75 -> 181
B22: 2024 | C22: ='Filtrado de Información'!AC57 -> 12,584 | D22: ='Filtrado de Información'!AC58 -> 12,136 | E22: ='Filtrado de Información'!E76 -> 190 | F22: ='Filtrado de Información'!F76 -> 144
B23: Fuente: Fuente: INEGI. Estadísticas de Defunciones Registradas (EDR). Hidalgo
B25: Cuadro 2
B26: Hidalgo: defunciones de 1 a 4 años por sexo según edad detallada, 2015-2024
C28: D1 | E28: D2 | G28: D3 | I28: D4
B29: Año | C29: Hombres | D29: Mujeres | E29: Hombres | F29: Mujeres | G29: Hombres | H29: Mujeres | I29: Hombres | J29: Mujeres
B30: 2015 | C30: ='Filtrado de Información'!E137 -> 22 | D30: ='Filtrado de Información'!F137 -> 18 | E30: ='Filtrado de Información'!E172 -> 16 | F30: ='Filtrado de Información'!F172 -> 14 | G30: ='Filtrado de Información'!E207 -> 9 | H30: ='Filtrado de Información'!F207 -> 6 | I30: ='Filtrado de Información'!E242 -> 9 | J30: ='Filtrado de Información'!F242 -> 6
B31: 2016 | C31: ='Filtrado de Información'!E138 -> 21 | D31: ='Filtrado de Información'!F138 -> 25 | E31: ='Filtrado de Información'!E173 -> 13 | F31: ='Filtrado de Información'!F173 -> 10 | G31: ='Filtrado de Información'!E208 -> 7 | H31: ='Filtrado de Información'!F208 -> 7 | I31: ='Filtrado de Información'!E243 -> 10 | J31: ='Filtrado de Información'!F243 -> 11
B32: 2017 | C32: ='Filtrado de Información'!E139 -> 20 | D32: ='Filtrado de Información'!F139 -> 19 | E32: ='Filtrado de Información'!E174 -> 17 | F32: ='Filtrado de Información'!F174 -> 7 | G32: ='Filtrado de Información'!E209 -> 8 | H32: ='Filtrado de Información'!F209 -> 8 | I32: ='Filtrado de Información'!E244 -> 9 | J32: ='Filtrado de Información'!F244 -> 7
B33: 2018 | C33: ='Filtrado de Información'!E140 -> 22 | D33: ='Filtrado de Información'!F140 -> 21 | E33: ='Filtrado de Información'!E175 -> 8 | F33: ='Filtrado de Información'!F175 -> 12 | G33: ='Filtrado de Información'!E210 -> 10 | H33: ='Filtrado de Información'!F210 -> 14 | I33: ='Filtrado de Información'!E245 -> 5 | J33: ='Filtrado de Información'!F245 -> 12
B34: 2019 | C34: ='Filtrado de Información'!E141 -> 22 | D34: ='Filtrado de Información'!F141 -> 28 | E34: ='Filtrado de Información'!E176 -> 12 | F34: ='Filtrado de Información'!F176 -> 15 | G34: ='Filtrado de Información'!E211 -> 9 | H34: ='Filtrado de Información'!F211 -> 5 | I34: ='Filtrado de Información'!E246 -> 7 | J34: ='Filtrado de Información'!F246 -> 2
B35: 2020 | C35: ='Filtrado de Información'!E142 -> 19 | D35: ='Filtrado de Información'!F142 -> 15 | E35: ='Filtrado de Información'!E177 -> 11 | F35: ='Filtrado de Información'!F177 -> 9 | G35: ='Filtrado de Información'!E212 -> 10 | H35: ='Filtrado de Información'!F212 -> 6 | I35: ='Filtrado de Información'!E247 -> 4 | J35: ='Filtrado de Información'!F247 -> 4
B36: 2021 | C36: ='Filtrado de Información'!E143 -> 20 | D36: ='Filtrado de Información'!F143 -> 17 | E36: ='Filtrado de Información'!E178 -> 7 | F36: ='Filtrado de Información'!F178 -> 13 | G36: ='Filtrado de Información'!E213 -> 10 | H36: ='Filtrado de Información'!F213 -> 7 | I36: ='Filtrado de Información'!E248 -> 12 | J36: ='Filtrado de Información'!F248 -> 4
B37: 2022 | C37: ='Filtrado de Información'!E144 -> 12 | D37: ='Filtrado de Información'!F144 -> 15 | E37: ='Filtrado de Información'!E179 -> 15 | F37: ='Filtrado de Información'!F179 -> 6 | G37: ='Filtrado de Información'!E214 -> 9 | H37: ='Filtrado de Información'!F214 -> 5 | I37: ='Filtrado de Información'!E249 -> 5 | J37: ='Filtrado de Información'!F249 -> 2
B38: 2023 | C38: ='Filtrado de Información'!E145 -> 22 | D38: ='Filtrado de Información'!F145 -> 14 | E38: ='Filtrado de Información'!E180 -> 16 | F38: ='Filtrado de Información'!F180 -> 9 | G38: ='Filtrado de Información'!E215 -> 6 | H38: ='Filtrado de Información'!F215 -> 11 | I38: ='Filtrado de Información'!E250 -> 9 | J38: ='Filtrado de Información'!F250 -> 10
B39: 2024 | C39: ='Filtrado de Información'!E146 -> 10 | D39: ='Filtrado de Información'!F146 -> 16 | E39: ='Filtrado de Información'!E181 -> 7 | F39: ='Filtrado de Información'!F181 -> 5 | G39: ='Filtrado de Información'!E216 -> 11 | H39: ='Filtrado de Información'!F216 -> 3 | I39: ='Filtrado de Información'!E251 -> 6 | J39: ='Filtrado de Información'!F251 -> 3
B40: Fuente: Fuente: INEGI. Estadísticas de Defunciones Registradas (EDR). Hidalgo
B42: Promedio de APV de aquellos que murieron antes de cumplir 1 año de edad: a0 hombres = 0,2 y a0 mujeres = 0,15
B43: Para las edades 1, 2, 3 y 4 utilizar los factores de Glover: a1 = 0,41, a2 = 0,47, a3 = 0,48 y a4 = 0,48

Sheet Diagrama de Lexis
B2: a0 | E2: HIDALGO: DIAGRAMA DE LEXIS, DEFUNCIONES MASCULINAS, 2017-2024 | W2: a0 | Z2: HIDALGO: DIAGRAMA DE LEXIS, DEFUNCIONES FEMENINAS, 2017-2024
D3: Edad (en años cumplidos)
E4: 5 | P4: =O5-P5 -> 18198.77 | R4: =Q5-R5 -> 17354.13 | T4: =S5-T5 -> 16306.69 | Y4: Edad (en años cumplidos) | Z4: 5 | AK4: =AJ5-AK5 -> 17874.72 | AM4: =AL5-AM5 -> 16627.28 | AO4: =AN5-AO5 -> 15723.75
B5: 0.48 | N5: =Datos!I36*(1-B5) -> 6.24 | O5: =N9-N8 -> 18201.37 | P5: =Datos!I37*(1-B5) -> 2.6 | Q5: =P9-P8 -> 17358.81 | R5: =Datos!I38*(1-B5) -> 4.68 | S5: =R9-R8 -> 16309.81 | T5: =Datos!I39*(1-B5) -> 3.12 | U5: =T9-T8 -> 13739.11 | W5: 0.48 | AI5: =Datos!J36*(1-W5) -> 2.08 | AJ5: =AI9-AI8 -> 17875.76 | AK5: =Datos!J37*(1-W5) -> 1.04 | AL5: =AK9-AK8 -> 16632.48 | AM5: =Datos!J38*(1-W5) -> 5.2 | AN5: =AM9-AM8 -> 15725.31 | AO5: =Datos!J39*(1-W5) -> 1.56 | AP5: =AO9-AO8 -> 13411.31
N8: =Datos!I36*B5 -> 5.76 | P8: =Datos!I37*B5 -> 2.4 | R8: =Datos!I38*B5 -> 4.32 | T8: =Datos!I39*B5 -> 2.88 | AI8: =Datos!J36*W5 -> 1.92 | AK8: =Datos!J37*W5 -> 0.96 | AM8: =Datos!J38*W5 -> 4.8 | AO8: =Datos!J39*W5 -> 1.44
E9: 4 | N9: =M10-N10 -> 18207.13 | P9: =O10-P10 -> 17361.21 | R9: =Q10-R10 -> 16314.13 | T9: =S10-T10 -> 13741.99 | Z9: 4 | AI9: =AH10-AI10 -> 17877.68 | AK9: =AJ10-AK10 -> 16633.44 | AM9: =AL10-AM10 -> 15730.11 | AO9: =AN10-AO10 -> 13412.75
B10: 0.48 | L10: =Datos!G35*(1-B10) -> 5.2 | M10: =L14-L13 -> 18212.33 | N10: =Datos!G36*(1-B10) -> 5.2 | O10: =N14-N13 -> 17365.89 | P10: =Datos!G37*(1-B10) -> 4.68 | Q10: =P14-P13 -> 16317.25 | R10: =Datos!G38*(1-B10) -> 3.12 | S10: =R14-R13 -> 13747.71 | T10: =Datos!G39*(1-B10) -> 5.72 | U10: =T14-T13 -> 13245.99 | W10: 0.48 | AG10: =Datos!H35*(1-W10) -> 3.12 | AH10: =AG14-AG13 -> 17881.32 | AI10: =Datos!H36*(1-W10) -> 3.64 | AJ10: =AI14-AI13 -> 16636.04 | AK10: =Datos!H37*(1-W10) -> 2.6 | AL10: =AK14-AK13 -> 15735.83 | AM10: =Datos!H38*(1-W10) -> 5.72 | AN10: =AM14-AM13 -> 13414.31 | AO10: =Datos!H39*(1-W10) -> 1.56 | AP10: =AO14-AO13 -> 12641.87
L13: =Datos!G35*B10 -> 4.8 | N13: =Datos!G36*B10 -> 4.8 | P13: =Datos!G37*B10 -> 4.32 | R13: =Datos!G38*B10 -> 2.88 | T13: =Datos!G39*B10 -> 5.28 | AG13: =Datos!H35*W10 -> 2.88 | AI13: =Datos!H36*W10 -> 3.36 | AK13: =Datos!H37*W10 -> 2.4 | AM13: =Datos!H38*W10 -> 5.28 | AO13: =Datos!H39*W10 -> 1.44
E14: 3 | L14: =K15-L15 -> 18217.13 | N14: =M15-N15 -> 17370.69 | P14: =O15-P15 -> 16321.57 | R14: =Q15-R15 -> 13750.59 | T14: =S15-T15 -> 13251.27 | Z14: 3 | AG14: =AF15-AG15 -> 17884.2 | AI14: =AH15-AI15 -> 16639.4 | AK14: =AJ15-AK15 -> 15738.23 | AM14: =AL15-AM15 -> 13419.59 | AO14: =AN15-AO15 -> 12643.31
B15: 0.47 | J15: =Datos!E34*(1-B15) -> 6.36 | K15: =J19-J18 -> 18222.96 | L15: =Datos!E35*(1-B15) -> 5.83 | M15: =L19-L18 -> 17374.4 | N15: =Datos!E36*(1-B15) -> 3.71 | O15: =N19-N18 -> 16329.52 | P15: =Datos!E37*(1-B15) -> 7.95 | Q15: =P19-P18 -> 13759.07 | R15: =Datos!E38*(1-B15) -> 8.48 | S15: =R19-R18 -> 13254.98 | T15: =Datos!E39*(1-B15) -> 3.71 | U15: =T19-T18 -> 13367.39 | W15: 0.47 | AE15: =Datos!F34*(1-W15) -> 7.95 | AF15: =AE19-AE18 -> 17888.97 | AG15: =Datos!F35*(1-W15) -> 4.77 | AH15: =AG19-AG18 -> 16646.29 | AI15: =Datos!F36*(1-W15) -> 6.89 | AJ15: =AI19-AI18 -> 15741.41 | AK15: =Datos!F37*(1-W15) -> 3.18 | AL15: =AK19-AK18 -> 13424.36 | AM15: =Datos!F38*(1-W15) -> 4.77 | AN15: =AM19-AM18 -> 12645.96 | AO15: =Datos!F39*(1-W15) -> 2.65 | AP15: =AO19-AO18 -> 13059.06
J18: =Datos!E34*B15 -> 5.64 | L18: =Datos!E35*B15 -> 5.17 | N18: =Datos!E36*B15 -> 3.29 | P18: =Datos!E37*B15 -> 7.05 | R18: =Datos!E38*B15 -> 7.52 | T18: =Datos!E39*B15 -> 3.29 | AE18: =Datos!F34*W15 -> 7.05 | AG18: =Datos!F35*W15 -> 4.23 | AI18: =Datos!F36*W15 -> 6.11 | AK18: =Datos!F37*W15 -> 2.82 | AM18: =Datos!F38*W15 -> 4.23 | AO18: =Datos!F39*W15 -> 2.35
E19: 2 | J19: =I20-J20 -> 18228.6 | L19: =K20-L20 -> 17379.57 | N19: =M20-N20 -> 16332.81 | P19: =O20-P20 -> 13766.12 | R19: =Q20-R20 -> 13262.5 | T19: =S20-T20 -> 13370.68 | Z19: 2 | AE19: =AD20-AE20 -> 17896.02 | AG19: =AF20-AG20 -> 16650.52 | AI19: =AH20-AI20 -> 15747.52 | AK19: =AJ20-AK20 -> 13427.18 | AM19: =AL20-AM20 -> 12650.19 | AO19: =AN20-AO20 -> 13061.41
B20: 0.41 | H20: =Datos!C33*(1-B20) -> 12.98 | I20: =H24-H23 -> 18241.58 | J20: =Datos!C34*(1-B20) -> 12.98 | K20: =J24-J23 -> 17390.78 | L20: =Datos!C35*(1-B20) -> 11.21 | M20: =L24-L23 -> 16344.61 | N20: =Datos!C36*(1-B20) -> 11.8 | O20: =N24-N23 -> 13773.2 | P20: =Datos!C37*(1-B20) -> 7.08 | Q20: =P24-P23 -> 13275.48 | R20: =Datos!C38*(1-B20) -> 12.98 | S20: =R24-R23 -> 13376.58 | T20: =Datos!C39*(1-B20) -> 5.9 | U20: =T24-T23 -> 13011.7 | W20: 0.41 | AC20: =Datos!D33*(1-W20) -> 12.39 | AD20: =AC24-AC23 -> 17912.54 | AE20: =Datos!D34*(1-W20) -> 16.52 | AF20: =AE24-AE23 -> 16659.37 | AG20: =Datos!D35*(1-W20) -> 8.85 | AH20: =AG24-AG23 -> 15757.55 | AI20: =Datos!D36*(1-W20) -> 10.03 | AJ20: =AI24-AI23 -> 13436.03 | AK20: =Datos!D37*(1-W20) -> 8.85 | AL20: =AK24-AK23 -> 12658.45 | AM20: =Datos!D38*(1-W20) -> 8.26 | AN20: =AM24-AM23 -> 13075.01 | AO20: =Datos!D39*(1-W25) -> 13.6 | AP20: =AO24-AO23 -> 12839.05
H23: =Datos!C33*B20 -> 9.02 | J23: =Datos!C34*B20 -> 9.02 | L23: =Datos!C35*B20 -> 7.79 | N23: =Datos!C36*B20 -> 8.2 | P23: =Datos!C37*B20 -> 4.92 | R23: =Datos!C38*B20 -> 9.02 | T23: =Datos!C39*B20 -> 4.1 | AC23: =Datos!D33*W20 -> 8.61 | AE23: =Datos!D34*W20 -> 11.48 | AG23: =Datos!D35*W20 -> 6.15 | AI23: =Datos!D36*W20 -> 6.97 | AK23: =Datos!D37*W20 -> 6.15 | AM23: =Datos!D38*W20 -> 5.74 | AO23: =Datos!D39*W25 -> 2.4
E24: 1 | H24: =G25-H25 -> 18250.6 | J24: =I25-J25 -> 17399.8 | L24: =K25-L25 -> 16352.4 | N24: =M25-N25 -> 13781.4 | P24: =O25-P25 -> 13280.4 | R24: =Q25-R25 -> 13385.6 | T24: =S25-T25 -> 13015.8 | Z24: 1 | AC24: =AB25-AC25 -> 17921.15 | AE24: =AD25-AE25 -> 16670.85 | AG24: =AF25-AG25 -> 15763.7 | AI24: =AH25-AI25 -> 13443 | AK24: =AJ25-AK25 -> 12664.6 | AM24: =AL25-AM25 -> 13080.75 | AO24: =AN25-AO25 -> 12841.45
B25: 0.2 | F25: =Datos!E15*0.8 -> 236 | G25: =F29-F28 -> 18461 | H25: =Datos!E16*(1-B25) -> 210.4 | I25: =H29-H28 -> 17621.4 | J25: =Datos!E17*(1-B25) -> 221.6 | K25: =J29-J28 -> 16503.6 | L25: =Datos!E18*(1-B25) -> 151.2 | M25: =L29-L28 -> 13962.2 | N25: =Datos!E19*(1-B25) -> 180.8 | O25: =N29-N28 -> 13478.8 | P25: =Datos!E20*(1-B25) -> 198.4 | Q25: =P29-P28 -> 13582.4 | R25: =Datos!E21*(1-B25) -> 196.8 | S25: =R29-R28 -> 13167.8 | T25: =Datos!E22*(1-B25) -> 152 | U25: =T29-T28 -> 12546 | W25: 0.15 | AA25: =Datos!F15*(1-W25) -> 181.9 | AB25: =AA29-AA28 -> 18103.9 | AC25: =Datos!F16*(1-W25) -> 182.75 | AD25: =AC29-AC28 -> 16835.75 | AE25: =Datos!F17*(1-W25) -> 164.9 | AF25: =AE29-AE28 -> 15892.9 | AG25: =Datos!F18*(1-W25) -> 129.2 | AH25: =AG29-AG28 -> 13606.2 | AI25: =Datos!F19*(1-W25) -> 163.2 | AJ25: =AI29-AI28 -> 12831.2 | AK25: =Datos!F20*(1-W25) -> 166.6 | AL25: =AK29-AK28 -> 13234.6 | AM25: =Datos!F21*(1-W25) -> 153.85 | AN25: =AM29-AM28 -> 12963.85 | AO25: =Datos!F22*(1-W25) -> 122.4 | AP25: =AO29-AO28 -> 12114.4
E28: 0 | F28: =Datos!E15*B25 -> 59 | H28: =Datos!E16*B25 -> 52.6 | J28: =Datos!E17*B25 -> 55.4 | L28: =Datos!E18*B25 -> 37.8 | N28: =Datos!E19*B25 -> 45.2 | P28: =Datos!E20*B25 -> 49.6 | R28: =Datos!E21*B25 -> 49.2 | T28: =Datos!E22*B25 -> 38 | Z28: 0 | AA28: =Datos!F15*W25 -> 32.1 | AC28: =Datos!F16*W25 -> 32.25 | AE28: =Datos!F17*W25 -> 29.1 | AG28: =Datos!F18*W25 -> 22.8 | AI28: =Datos!F19*W25 -> 28.8 | AK28: =Datos!F20*W25 -> 29.4 | AM28: =Datos!F21*W25 -> 27.15 | AO28: =Datos!F22*W25 -> 21.6
F29: =Datos!C15 -> 18,520 | H29: =Datos!C16 -> 17,674 | J29: =Datos!C17 -> 16,559 | L29: =Datos!C18 -> 14,000 | N29: =Datos!C19 -> 13,524 | P29: =Datos!C20 -> 13632 | R29: =Datos!C21 -> 13,217 | T29: =Datos!C22 -> 12,584 | AA29: =Datos!D15 -> 18,136 | AC29: =Datos!D16 -> 16,868 | AE29: =Datos!D17 -> 15,922 | AG29: =Datos!D18 -> 13,629 | AI29: =Datos!D19 -> 12,860 | AK29: =Datos!D20 -> 13264 | AM29: =Datos!D21 -> 12,991 | AO29: =Datos!D22 -> 12,136
F30: 2017 | H30: 2018 | J30: 2019 | L30: 2020 | N30: 2021 | P30: 2022 | R30: 2023 | T30: 2024 | AA30: 2017 | AC30: 2018 | AE30: 2019 | AG30: 2020 | AI30: 2021 | AK30: 2022 | AM30: 2023 | AO30: 2024
F31: Año | AA31: Año
F33: Llenar con los datos de los de la planilla "datos" utilizando los ax.

Sheet TMI
B2: Año de nacimiento | C2: TMI Cohorte | J2: Año | K2: TMI refinada
C3: Hombres | D3: Mujeres | K3: Hombres | N3: Mujeres
B4: 2020 | C4: =(('Diagrama de Lexis'!N25+'Diagrama de Lexis'!L28)/'Diagrama de Lexis'!L29)*1000 -> 15.614286 | D4: =(('Diagrama de Lexis'!AI25+'Diagrama de Lexis'!AG28)/'Diagrama de Lexis'!AG29)*1000 -> 13.64737 | K4: αp0 | L4: δp0 | M4: q0 | N4: αp0 | O4: δp0 | P4: q0
B5: 2021 | C5: =(('Diagrama de Lexis'!P25+'Diagrama de Lexis'!N28)/'Diagrama de Lexis'!N29)*1000 -> 18.012422 | D5: =(('Diagrama de Lexis'!AK25+'Diagrama de Lexis'!AI28)/'Diagrama de Lexis'!AI29)*1000 -> 15.194401 | J5: 2002
B6: 2022 | C6: =(('Diagrama de Lexis'!R25 +'Diagrama de Lexis'!P28)/'Diagrama de Lexis'!P29)*1000 -> 18.075117 | D6: =(('Diagrama de Lexis'!AM25+'Diagrama de Lexis'!AK28)/'Diagrama de Lexis'!AK29)*1000 -> 13.815591 | J6: 2003
B7: 2023 | C7: =(('Diagrama de Lexis'!T25+'Diagrama de Lexis'!R28)/'Diagrama de Lexis'!R29)*1000 -> 15.222819 | D7: =(('Diagrama de Lexis'!AO25+'Diagrama de Lexis'!AM28)/'Diagrama de Lexis'!AM29)*1000 -> 11.511816 | J7: 2004
J8: 2005
B9: Año | C9: TMI clásica
C10: Hombres | D10: Mujeres
B11: 2020 | C11: =('Diagrama de Lexis'!L10+'Diagrama de Lexis'!L13+'Diagrama de Lexis'!L15+'Diagrama de Lexis'!L18+'Diagrama de Lexis'!L20+'Diagrama de Lexis'!L23+'Diagrama de Lexis'!L25+'Diagrama de Lexis'!L28)/'Diagrama de Lexis'!L29 -> 0.016357143 | D11: =('Diagrama de Lexis'!AG10+'Diagrama de Lexis'!AG13+'Diagrama de Lexis'!AG15+'Diagrama de Lexis'!AG18+'Diagrama de Lexis'!AG20+'Diagrama de Lexis'!AG23+'Diagrama de Lexis'!AG25+'Diagrama de Lexis'!AG28)/'Diagrama de Lexis'!AG29 -> 0.013353878
B12: 2021 | C12: =('Diagrama de Lexis'!N5+'Diagrama de Lexis'!N8+'Diagrama de Lexis'!N10+'Diagrama de Lexis'!N13+'Diagrama de Lexis'!N15+'Diagrama de Lexis'!N18+'Diagrama de Lexis'!N20+'Diagrama de Lexis'!N23+'Diagrama de Lexis'!N25+'Diagrama de Lexis'!N28)/'Diagrama de Lexis'!N29 -> 0.020334221 | D12: =('Diagrama de Lexis'!AI5+'Diagrama de Lexis'!AI8+'Diagrama de Lexis'!AI10+'Diagrama de Lexis'!AI13+'Diagrama de Lexis'!AI15+'Diagrama de Lexis'!AI18+'Diagrama de Lexis'!AI20+'Diagrama de Lexis'!AI23+'Diagrama de Lexis'!AI25+'Diagrama de Lexis'!AI28)/'Diagrama de Lexis'!AI29 -> 0.018118196
B13: 2022 | C13: =('Diagrama de Lexis'!P5+'Diagrama de Lexis'!P8+'Diagrama de Lexis'!P10+'Diagrama de Lexis'!P13+'Diagrama de Lexis'!P15+'Diagrama de Lexis'!P18+'Diagrama de Lexis'!P20+'Diagrama de Lexis'!P23+'Diagrama de Lexis'!P25+'Diagrama de Lexis'!P28)/'Diagrama de Lexis'!P29 -> 0.021200117 | D13: =('Diagrama de Lexis'!AK5+'Diagrama de Lexis'!AK8+'Diagrama de Lexis'!AK10+'Diagrama de Lexis'!AK13+'Diagrama de Lexis'!AK15+'Diagrama de Lexis'!AK18+'Diagrama de Lexis'!AK20+'Diagrama de Lexis'!AK23+'Diagrama de Lexis'!AK25+'Diagrama de Lexis'!AK28)/'Diagrama de Lexis'!AK29 -> 0.016887817
B14: 2023 | C14: =('Diagrama de Lexis'!R5+'Diagrama de Lexis'!R8+'Diagrama de Lexis'!R10+'Diagrama de Lexis'!R13+'Diagrama de Lexis'!R15+'Diagrama de Lexis'!R18+'Diagrama de Lexis'!R20+'Diagrama de Lexis'!R23+'Diagrama de Lexis'!R25+'Diagrama de Lexis'!R28)/'Diagrama de Lexis'!R29 -> 0.02262238 | D14: =('Diagrama de Lexis'!AM5+'Diagrama de Lexis'!AM8+'Diagrama de Lexis'!AM10+'Diagrama de Lexis'!AM13+'Diagrama de Lexis'!AM15+'Diagrama de Lexis'!AM18+'Diagrama de Lexis'!AM20+'Diagrama de Lexis'!AM23+'Diagrama de Lexis'!AM25+'Diagrama de Lexis'!AM28)/'Diagrama de Lexis'!AM29 -> 0.017319683
